version: incident/v1
id: 5yjxd5tr78kz
name: Grafana Cloud having a datasource with PDC enabled using localhost address are getting 403 status responses.
impact: major
systems:
    - pmc3jw5xsjwz
    - 84fnwytt05df
    - 3sk6cpgms8yn
    - hmyx8mtn3tjq
    - wg7t1g2762jh
    - ht5t547d4vlk
    - mbk5fz2pkjx8
    - r4t5cjg79lkv
    - 2lgxvw5jzjy2
    - xp9dh2867dhp
    - 7hzxytvzk3mz
    - y46ddhgystcm
    - 83pzb618q8t9
    - z9wm2b60vf8f
    - qtptj232t43m
    - 2htzkr2r80lm
    - fd85rg7yrqww
    - 22lqyzyw46nj
    - y081wmnk39py
timeline:
    - ts: "2024-10-28 12:49:42"
      description: All Grafana Cloud instances using a datasource with PDC enabled, which are attempting to connect to a localhost address are receiving 403 status responses - queries using these datasources will fail with 403 status error. We've identified the issue and working on resolving it.
    - ts: "2024-10-29 09:29:30"
      description: A fix has been implemented and we are monitoring the results.
    - ts: "2024-10-29 14:47:49"
      description: The incident has been resolved.
      resolved: true
